[2025-02-02T06:17:48.481+0000] {processor.py:186} INFO - Started process (PID=165) to work on /opt/airflow/dags/transaction_facts_generator_dag.py
[2025-02-02T06:17:48.482+0000] {processor.py:914} INFO - Processing file /opt/airflow/dags/transaction_facts_generator_dag.py for tasks to queue
[2025-02-02T06:17:48.488+0000] {logging_mixin.py:190} INFO - [2025-02-02T06:17:48.488+0000] {dagbag.py:588} INFO - Filling up the DagBag from /opt/airflow/dags/transaction_facts_generator_dag.py
[2025-02-02T06:17:48.494+0000] {logging_mixin.py:190} INFO - [2025-02-02T06:17:48.492+0000] {dagbag.py:387} ERROR - Failed to import: /opt/airflow/dags/transaction_facts_generator_dag.py
Traceback (most recent call last):
  File "/home/airflow/.local/lib/python3.12/site-packages/airflow/models/dagbag.py", line 383, in parse
    loader.exec_module(new_module)
  File "<frozen importlib._bootstrap_external>", line 995, in exec_module
  File "<frozen importlib._bootstrap>", line 488, in _call_with_frames_removed
  File "/opt/airflow/dags/transaction_facts_generator_dag.py", line 6, in <module>
    from kafka_operator import KafkaProduceOperator
ModuleNotFoundError: No module named 'kafka_operator'
[2025-02-02T06:17:48.495+0000] {processor.py:927} WARNING - No viable dags retrieved from /opt/airflow/dags/transaction_facts_generator_dag.py
[2025-02-02T06:17:48.532+0000] {processor.py:208} INFO - Processing /opt/airflow/dags/transaction_facts_generator_dag.py took 0.059 seconds
[2025-02-02T06:18:18.639+0000] {processor.py:186} INFO - Started process (PID=471) to work on /opt/airflow/dags/transaction_facts_generator_dag.py
[2025-02-02T06:18:18.640+0000] {processor.py:914} INFO - Processing file /opt/airflow/dags/transaction_facts_generator_dag.py for tasks to queue
[2025-02-02T06:18:18.641+0000] {logging_mixin.py:190} INFO - [2025-02-02T06:18:18.641+0000] {dagbag.py:588} INFO - Filling up the DagBag from /opt/airflow/dags/transaction_facts_generator_dag.py
[2025-02-02T06:18:18.644+0000] {logging_mixin.py:190} INFO - [2025-02-02T06:18:18.643+0000] {dagbag.py:387} ERROR - Failed to import: /opt/airflow/dags/transaction_facts_generator_dag.py
Traceback (most recent call last):
  File "/home/airflow/.local/lib/python3.12/site-packages/airflow/models/dagbag.py", line 383, in parse
    loader.exec_module(new_module)
  File "<frozen importlib._bootstrap_external>", line 995, in exec_module
  File "<frozen importlib._bootstrap>", line 488, in _call_with_frames_removed
  File "/opt/airflow/dags/transaction_facts_generator_dag.py", line 6, in <module>
    from kafka_operator import KafkaProduceOperator
ModuleNotFoundError: No module named 'kafka_operator'
[2025-02-02T06:18:18.644+0000] {processor.py:927} WARNING - No viable dags retrieved from /opt/airflow/dags/transaction_facts_generator_dag.py
[2025-02-02T06:18:18.665+0000] {processor.py:208} INFO - Processing /opt/airflow/dags/transaction_facts_generator_dag.py took 0.032 seconds
[2025-02-02T06:18:49.197+0000] {processor.py:186} INFO - Started process (PID=777) to work on /opt/airflow/dags/transaction_facts_generator_dag.py
[2025-02-02T06:18:49.199+0000] {processor.py:914} INFO - Processing file /opt/airflow/dags/transaction_facts_generator_dag.py for tasks to queue
[2025-02-02T06:18:49.201+0000] {logging_mixin.py:190} INFO - [2025-02-02T06:18:49.201+0000] {dagbag.py:588} INFO - Filling up the DagBag from /opt/airflow/dags/transaction_facts_generator_dag.py
[2025-02-02T06:18:49.204+0000] {logging_mixin.py:190} INFO - [2025-02-02T06:18:49.203+0000] {dagbag.py:387} ERROR - Failed to import: /opt/airflow/dags/transaction_facts_generator_dag.py
Traceback (most recent call last):
  File "/home/airflow/.local/lib/python3.12/site-packages/airflow/models/dagbag.py", line 383, in parse
    loader.exec_module(new_module)
  File "<frozen importlib._bootstrap_external>", line 995, in exec_module
  File "<frozen importlib._bootstrap>", line 488, in _call_with_frames_removed
  File "/opt/airflow/dags/transaction_facts_generator_dag.py", line 6, in <module>
    from kafka_operator import KafkaProduceOperator
ModuleNotFoundError: No module named 'kafka_operator'
[2025-02-02T06:18:49.205+0000] {processor.py:927} WARNING - No viable dags retrieved from /opt/airflow/dags/transaction_facts_generator_dag.py
[2025-02-02T06:18:49.226+0000] {processor.py:208} INFO - Processing /opt/airflow/dags/transaction_facts_generator_dag.py took 0.037 seconds
[2025-02-02T06:19:19.573+0000] {processor.py:186} INFO - Started process (PID=1083) to work on /opt/airflow/dags/transaction_facts_generator_dag.py
[2025-02-02T06:19:19.575+0000] {processor.py:914} INFO - Processing file /opt/airflow/dags/transaction_facts_generator_dag.py for tasks to queue
[2025-02-02T06:19:19.577+0000] {logging_mixin.py:190} INFO - [2025-02-02T06:19:19.576+0000] {dagbag.py:588} INFO - Filling up the DagBag from /opt/airflow/dags/transaction_facts_generator_dag.py
[2025-02-02T06:19:19.580+0000] {logging_mixin.py:190} INFO - [2025-02-02T06:19:19.579+0000] {dagbag.py:387} ERROR - Failed to import: /opt/airflow/dags/transaction_facts_generator_dag.py
Traceback (most recent call last):
  File "/home/airflow/.local/lib/python3.12/site-packages/airflow/models/dagbag.py", line 383, in parse
    loader.exec_module(new_module)
  File "<frozen importlib._bootstrap_external>", line 995, in exec_module
  File "<frozen importlib._bootstrap>", line 488, in _call_with_frames_removed
  File "/opt/airflow/dags/transaction_facts_generator_dag.py", line 6, in <module>
    from kafka_operator import KafkaProduceOperator
ModuleNotFoundError: No module named 'kafka_operator'
[2025-02-02T06:19:19.581+0000] {processor.py:927} WARNING - No viable dags retrieved from /opt/airflow/dags/transaction_facts_generator_dag.py
[2025-02-02T06:19:19.602+0000] {processor.py:208} INFO - Processing /opt/airflow/dags/transaction_facts_generator_dag.py took 0.038 seconds
[2025-02-02T06:19:49.913+0000] {processor.py:186} INFO - Started process (PID=1389) to work on /opt/airflow/dags/transaction_facts_generator_dag.py
[2025-02-02T06:19:49.914+0000] {processor.py:914} INFO - Processing file /opt/airflow/dags/transaction_facts_generator_dag.py for tasks to queue
[2025-02-02T06:19:49.916+0000] {logging_mixin.py:190} INFO - [2025-02-02T06:19:49.916+0000] {dagbag.py:588} INFO - Filling up the DagBag from /opt/airflow/dags/transaction_facts_generator_dag.py
[2025-02-02T06:19:49.919+0000] {logging_mixin.py:190} INFO - [2025-02-02T06:19:49.918+0000] {dagbag.py:387} ERROR - Failed to import: /opt/airflow/dags/transaction_facts_generator_dag.py
Traceback (most recent call last):
  File "/home/airflow/.local/lib/python3.12/site-packages/airflow/models/dagbag.py", line 383, in parse
    loader.exec_module(new_module)
  File "<frozen importlib._bootstrap_external>", line 995, in exec_module
  File "<frozen importlib._bootstrap>", line 488, in _call_with_frames_removed
  File "/opt/airflow/dags/transaction_facts_generator_dag.py", line 6, in <module>
    from kafka_operator import KafkaProduceOperator
ModuleNotFoundError: No module named 'kafka_operator'
[2025-02-02T06:19:49.919+0000] {processor.py:927} WARNING - No viable dags retrieved from /opt/airflow/dags/transaction_facts_generator_dag.py
[2025-02-02T06:19:49.940+0000] {processor.py:208} INFO - Processing /opt/airflow/dags/transaction_facts_generator_dag.py took 0.032 seconds
[2025-02-02T06:20:20.143+0000] {processor.py:186} INFO - Started process (PID=1695) to work on /opt/airflow/dags/transaction_facts_generator_dag.py
[2025-02-02T06:20:20.145+0000] {processor.py:914} INFO - Processing file /opt/airflow/dags/transaction_facts_generator_dag.py for tasks to queue
[2025-02-02T06:20:20.147+0000] {logging_mixin.py:190} INFO - [2025-02-02T06:20:20.147+0000] {dagbag.py:588} INFO - Filling up the DagBag from /opt/airflow/dags/transaction_facts_generator_dag.py
[2025-02-02T06:20:20.150+0000] {logging_mixin.py:190} INFO - [2025-02-02T06:20:20.149+0000] {dagbag.py:387} ERROR - Failed to import: /opt/airflow/dags/transaction_facts_generator_dag.py
Traceback (most recent call last):
  File "/home/airflow/.local/lib/python3.12/site-packages/airflow/models/dagbag.py", line 383, in parse
    loader.exec_module(new_module)
  File "<frozen importlib._bootstrap_external>", line 995, in exec_module
  File "<frozen importlib._bootstrap>", line 488, in _call_with_frames_removed
  File "/opt/airflow/dags/transaction_facts_generator_dag.py", line 6, in <module>
    from kafka_operator import KafkaProduceOperator
ModuleNotFoundError: No module named 'kafka_operator'
[2025-02-02T06:20:20.150+0000] {processor.py:927} WARNING - No viable dags retrieved from /opt/airflow/dags/transaction_facts_generator_dag.py
[2025-02-02T06:20:20.172+0000] {processor.py:208} INFO - Processing /opt/airflow/dags/transaction_facts_generator_dag.py took 0.035 seconds
