[2025-02-12T16:08:32.706+0000] {taskinstance.py:1157} INFO - Dependencies all met for dep_context=non-requeueable deps ti=<TaskInstance: transaction_facts_generator.generate_txn_fact_data scheduled__2025-01-25T17:00:00+00:00 [queued]>
[2025-02-12T16:08:32.726+0000] {taskinstance.py:1157} INFO - Dependencies all met for dep_context=requeueable deps ti=<TaskInstance: transaction_facts_generator.generate_txn_fact_data scheduled__2025-01-25T17:00:00+00:00 [queued]>
[2025-02-12T16:08:32.727+0000] {taskinstance.py:1359} INFO - Starting attempt 1 of 4
[2025-02-12T16:08:32.762+0000] {taskinstance.py:1380} INFO - Executing <Task(KafkaProduceOperator): generate_txn_fact_data> on 2025-01-25 17:00:00+00:00
[2025-02-12T16:08:32.780+0000] {standard_task_runner.py:57} INFO - Started process 5722 to run task
[2025-02-12T16:08:32.788+0000] {standard_task_runner.py:84} INFO - Running: ['***', 'tasks', 'run', 'transaction_facts_generator', 'generate_txn_fact_data', 'scheduled__2025-01-25T17:00:00+00:00', '--job-id', '97', '--raw', '--subdir', 'DAGS_FOLDER/transaction_facts_generator_dag.py', '--cfg-path', '/tmp/tmpqbhalo4c']
[2025-02-12T16:08:32.795+0000] {standard_task_runner.py:85} INFO - Job 97: Subtask generate_txn_fact_data
[2025-02-12T16:08:32.940+0000] {task_command.py:415} INFO - Running <TaskInstance: transaction_facts_generator.generate_txn_fact_data scheduled__2025-01-25T17:00:00+00:00 [running]> on host 5879df32f101
[2025-02-12T16:08:33.382+0000] {taskinstance.py:1660} INFO - Exporting env vars: AIRFLOW_CTX_DAG_EMAIL='hoyseiha@gmail.com' AIRFLOW_CTX_DAG_OWNER='***' AIRFLOW_CTX_DAG_ID='transaction_facts_generator' AIRFLOW_CTX_TASK_ID='generate_txn_fact_data' AIRFLOW_CTX_EXECUTION_DATE='2025-01-25T17:00:00+00:00' AIRFLOW_CTX_TRY_NUMBER='1' AIRFLOW_CTX_DAG_RUN_ID='scheduled__2025-01-25T17:00:00+00:00'
[2025-02-12T16:08:50.202+0000] {conn.py:1527} WARNING - DNS lookup failed for kafka_broker:9092, exception was [Errno -3] Temporary failure in name resolution. Is your advertised.listeners (called advertised.host.name before Kafka 9) correct and resolvable?
[2025-02-12T16:08:51.390+0000] {conn.py:315} ERROR - DNS lookup failed for kafka_broker:9092 (0)
[2025-02-12T16:08:51.397+0000] {conn.py:1205} INFO - Probing node bootstrap-0 broker version
[2025-02-12T16:08:51.891+0000] {taskinstance.py:1935} ERROR - Task failed with exception
Traceback (most recent call last):
  File "/opt/airflow/plugins/kafka_operator.py", line 53, in execute
    producer = KafkaProducer(
  File "/home/airflow/.local/lib/python3.8/site-packages/kafka/producer/kafka.py", line 381, in __init__
    client = KafkaClient(metrics=self._metrics, metric_group_prefix='producer',
  File "/home/airflow/.local/lib/python3.8/site-packages/kafka/client_async.py", line 244, in __init__
    self.config['api_version'] = self.check_version(timeout=check_timeout)
  File "/home/airflow/.local/lib/python3.8/site-packages/kafka/client_async.py", line 927, in check_version
    raise Errors.NoBrokersAvailable()
kafka.errors.NoBrokersAvailable: NoBrokersAvailable
[2025-02-12T16:08:51.973+0000] {taskinstance.py:1398} INFO - Marking task as UP_FOR_RETRY. dag_id=transaction_facts_generator, task_id=generate_txn_fact_data, execution_date=20250125T170000, start_date=20250212T160832, end_date=20250212T160851
[2025-02-12T16:08:52.050+0000] {standard_task_runner.py:104} ERROR - Failed to execute job 97 for task generate_txn_fact_data (NoBrokersAvailable; 5722)
[2025-02-12T16:08:52.084+0000] {local_task_job_runner.py:228} INFO - Task exited with return code 1
[2025-02-12T16:08:52.168+0000] {taskinstance.py:2776} INFO - 0 downstream tasks scheduled from follow-on schedule check
